Workbook

Sheet User Input
A1: 1. In the next column, enter today's date (mm/dd/yyyy). | B1: 46024
A2: 2. In the next column, enter the first year of your ladder (yyyy). In the column immediately to the right of that column, enter the last year of your ladder (yyyy) [Note that the first year may not be earlier than the current year, and the last year may not be more than 30 years after the current year (as no TIPS have more than a 30-year maturity). | B2: 2028 | C2: 2066
A3: 3. In the next column, enter the most common amount of after-tax "real" income do you want to realize from your TIPS ladder in each year. [Note: I picked $33,000 in Jan 2023 and then inflated using CPI-U.] | B3: 37000
A4: 4. In the next columns, starting with the earliest applicable year, enter the years (one year per column in the yyyy format) in which you want to realize an amount of "real" income that differs from the most common amount entered in response to question 3. Then see question 5. | B4: 2033 | C4: 2040
A5: 5. Below each of the applicable years entered in response to question 4, enter the amount of "real" income you want to realize in that year. [Note: Because, as of the preparation of ths spreadsheet, no TIPS that mature in year 2035 through year 2039 (the "Gap Years"), the user may want to increase the amount of desired "real" income in 2033 and 2040 to cover the Gap Years."] | B5: 37000 | C5: 148000
A6: 6. If you already own TIPS that you want to be included in your ladder, answer questions (a), (b), (c), and (d) immediately below.
A7: a. In the next columns, enter the maturity dates of such existing TIPS (mm/dd/yyyy). If you have existing TIPS with the same maturity date but with different coupon rates, enter the date multiple times (in multiple columns), once for each coupon rate. [Mike to think through what happens if there are TIPS with the same maturity date and coupon but different issue dates (none of which currently exist), thus having different Index Factors. Should I require entry of Issue Date (which is not in Fidelity download) or Cusip?] | E7: 46767 | F7: 47133 | G7: 47498 | H7: 47863 | I7: 48319 | J7: 48594 | K7: 48959 | L7: 49324 | M7: 49689 | N7: 51181 | O7: 51547 | P7: 51912 | Q7: 52277 | R7: 52642 | S7: 53008 | T7: 53373 | U7: 53738 | V7: 54103 | W7: 54469 | X7: 54834 | Y7: 55199 | Z7: 55564 | AA7: 55930 | AB7: 56295 | AC7: 56660
A8: b. In the next columns, enter the stated coupon rate of the TIPS maturing on such date. | E8: 0.005 | F8: 0.025 | G8: 0.00125 | H8: 0.00125 | I8: 0.03375 | J8: 0.01125 | K8: 0.0175 | L8: 0.02125 | M8: 0.01875 | N8: 0.02125 | O8: 0.02125 | P8: 0.0075 | Q8: 0.00625 | R8: 0.01375 | S8: 0.0075 | T8: 0.01 | U8: 0.00875 | V8: 0.01 | W8: 0.01 | X8: 0.0025 | Y8: 0.00125 | Z8: 0.00125 | AA8: 0.015 | AB8: 0.02125 | AC8: 0.02375
A9: c. In the next columns, enter the quantity of such existing TIPS (each TIPS having an original principal amount of $1,000) that you hold in a regular taxable brokerage account. | E9: 25 | F9: 22 | G9: 26 | H9: 0 | I9: 15 | J9: 19 | N9: 0 | O9: 0 | P9: 9 | Q9: 15 | R9: 15 | T9: 8 | U9: 8 | V9: 8 | W9: 8 | X9: 4 | Y9: 18 | Z9: 19 | AB9: 11 | AC9: 33
A10: d. In the next columns, enter the quantity of such existing TIPS (each TIPS having an original principal amount of $1,000) that you hold in a pretax retirement account. | H10: 10 | J10: 24 | L10: 33 | M10: 39 | N10: 131 | O10: 30 | P10: 20 | Q10: 13 | R10: 13 | S10: 33 | T10: 24 | U10: 24 | V10: 25 | W10: 25 | X10: 32 | Y10: 15 | Z10: 16 | AA10: 14 | AC10: 2
A11: e. In the next columns, enter the quantity of such existing TIPS (each TIPS having an original principal amount of $1,000) that you hold in a Roth account. | H11: 18 | K11: 34 | AA11: 22 | AB11: 23
A12: 7. To "tax effect" the calculations in this spreadsheet, replace the percentage in the next column with your marginal income tax rate. Doing so will (i) except with respect to TIPS held in a Roth account, cause the "Current Dollar Annual Coupon Payments, Adjusted for Taxes" to be reduced based on such tax rate, and (ii) with respect to TIPS owned in a pretax retirement account, cause the "Principal of TIPS Already Owned" to be reduced based on such tax rate. Note that there is no tax effect for the "phantom income" of TIPS held in regular taxable brokerage accounts. | B12: 0.24

Sheet Ladder
A1: Maturity Year | B1: Maturity Date | C1: Coupon Rate | D1: Number of TIPS Already Owned in Regular Taxable Brokerage Accounts | E1: Uninflated Original Principal of TIPS Already Owned in Regular Taxable Brokerage Accounts | F1: Number of TIPS Already Owned in Pretax Retirement Accounts | G1: Uninflated Original Principal of TIPS Already Owned in Pretax Retirement Accounts | H1: Uninflated Original Principal of TIPS Already Owned in Pretax Retirement Accounts (Adjusted for Taxes) | I1: Number of TIPS Already Owned in Roth Accounts | J1: Uninflated Original Principal of TIPS Already Owned in Roth Accounts | K1: Inflation Factor/Index Ratio | L1: Inflated Principal of TIPS Already Owned (Tax-Adjusted for TIPS Already Owned in Pretax Retirement Accounts) | N1: Current Dollar Annual Coupon Payments, Adjusted (except with respect to TIPS Held in a Roth Account) for Taxes | P1: Ladder Year | Q1: Inflated Principal of TIPS Already Owned (Tax-Adjusted for TIPS Owned in Pretax Retirement Accounts) Per Ladder Year | R1: After-Tax Desired "Real" Income Per Ladder Year | S1: After-Tax"Real" Income Surplus/Shortfall Per Ladder Year (Takes into account the applicable year's maturing principal plus interest received that year on current and future maturing TIPS)
B2: [Download] | C2: [Download] | K2: [Download] | L2: [Note: Taxes on the inflation adjustment to the principal of TIPS held in Regular Taxable Brokerage Accounts are not taken into account, as it is not possible to anticipate what the inflation adjustments will be.] | S2: [For a later draft, consider reducing this number for partial year interest in the first and last year of a bond.]
P3: =IF(AND(Ladder!A3>='User Input'!B$2, Ladder!A3<='User Input'!C$2),Ladder!A3,"") | R3: =IF(P3="","",'User Input'!B$3)
A4: =IF(OR(TEXT(B3,"YYYY")<TEXT(B4,"YYYY"),ISBLANK(TEXT(B3,"YYYY"))),YEAR(B4),"") -> 2026 | B4: ='[1]Inflation Factors'!$C2 -> 46127 | C4: =('[1]Inflation Factors'!$B2)/100 -> 0.00125 | D4: {=IFERROR(INDEX('User Input'!$B$9:$AAD$9, ,_xlfn.XMATCH(B4&C4, 'User Input'!$B$7:$AAD$7&'User Input'!$B$8:$AAD$8)),"")} | E4: =IF(D4="","",D4*1000) | F4: {=IFERROR(INDEX('User Input'!$B$10:$AAD$10, ,_xlfn.XMATCH(B4&C4, 'User Input'!$B$7:$AAD$7&'User Input'!$B$8:$AAD$8)),"")} | G4: =IF(F4="","",F4*1000) | H4: =IF(F4="","",F4*1000*(100%-'User Input'!$B$12)) | I4: {=IFERROR(INDEX('User Input'!$B$11:$AAD$11, ,_xlfn.XMATCH(B4&C4, 'User Input'!$B$7:$AAD$7&'User Input'!$B$8:$AAD$8)),"")} | J4: =IF(I4="","",I4*1000) | K4: ='[1]Inflation Factors'!$H2 -> 1.23729 | L4: =IF(AND(E4="",G4="",J4=""),"",(E4+G4+J4)*K4) | N4: =IF(L4="","",(C4*L4*(100%-'User Input'!$B$12))+(C4*J4*K4*'User Input'!$B$12)) | P4: =IF(AND(Ladder!A4>='User Input'!B$2, Ladder!A4<='User Input'!C$2),Ladder!A4,"") | Q4: =IF(P4="","", SUMIFS($L$4:$L$89, $B$4:$B$89, ">="&DATE(P4,1,1),$B$4:$B$89,"<"&DATE(P4+1,1,1))) | R4: {=IF(P4="","",IFERROR(INDEX('User Input'!$B$5:$DD$5,,_xlfn.XMATCH(P4,'User Input'!$B$4:$DD$4)),'User Input'!$B$3))} | S4: =IF(R4="","",(Q4+SUM(N4:N89)-R4))
A5: =IF(OR(TEXT(B4,"YYYY")<TEXT(B5,"YYYY"),ISBLANK(TEXT(B4,"YYYY"))),YEAR(B5),"") | B5: ='[1]Inflation Factors'!$C3 -> 46218 | C5: =('[1]Inflation Factors'!$B3)/100 -> 0.00125 | D5: {=IFERROR(INDEX('User Input'!$B$9:$AAD$9, ,_xlfn.XMATCH(B5&C5, 'User Input'!$B$7:$AAD$7&'User Input'!$B$8:$AAD$8)),"")} | E5: =IF(D5="","",D5*1000) | F5: {=IFERROR(INDEX('User Input'!$B$10:$AAD$10, ,_xlfn.XMATCH(B5&C5, 'User Input'!$B$7:$AAD$7&'User Input'!$B$8:$AAD$8)),"")} | G5: =IF(F5="","",F5*1000) | H5: =IF(F5="","",F5*1000*(100%-'User Input'!$B$12)) | I5: {=IFERROR(INDEX('User Input'!$B$11:$AAD$11, ,_xlfn.XMATCH(B5&C5, 'User Input'!$B$7:$AAD$7&'User Input'!$B$8:$AAD$8)),"")} | J5: =IF(I5="","",I5*1000) | K5: ='[1]Inflation Factors'!$H3 -> 1.35368 | L5: =IF(AND(E5="",G5="",J5=""),"",(E5+G5+J5)*K5) | N5: =IF(L5="","",(C5*L5*(100%-'User Input'!$B$12))+(C5*J5*K5*'User Input'!$B$12)) | P5: =IF(AND(Ladder!A5>='User Input'!B$2, Ladder!A5<='User Input'!C$2),Ladder!A5,"") | Q5: =IF(P5="","", SUMIFS($L$4:$L$89, $B$4:$B$89, ">="&DATE(P5,1,1),$B$4:$B$89,"<"&DATE(P5+1,1,1))) | R5: {=IF(P5="","",IFERROR(INDEX('User Input'!$B$5:$DD$5,,_xlfn.XMATCH(P5,'User Input'!$B$4:$DD$4)),'User Input'!$B$3))} | S5: =IF(R5="","",(Q5+SUM(N5:N90)-R5))
A6: =IF(OR(TEXT(B5,"YYYY")<TEXT(B6,"YYYY"),ISBLANK(TEXT(B5,"YYYY"))),YEAR(B6),"") | B6: ='[1]Inflation Factors'!$C4 -> 46310 | C6: =('[1]Inflation Factors'!$B4)/100 -> 0.00125 | D6: {=IFERROR(INDEX('User Input'!$B$9:$AAD$9, ,_xlfn.XMATCH(B6&C6, 'User Input'!$B$7:$AAD$7&'User Input'!$B$8:$AAD$8)),"")} | E6: =IF(D6="","",D6*1000) | F6: {=IFERROR(INDEX('User Input'!$B$10:$AAD$10, ,_xlfn.XMATCH(B6&C6, 'User Input'!$B$7:$AAD$7&'User Input'!$B$8:$AAD$8)),"")} | G6: =IF(F6="","",F6*1000) | H6: =IF(F6="","",F6*1000*(100%-'User Input'!$B$12)) | I6: {=IFERROR(INDEX('User Input'!$B$11:$AAD$11, ,_xlfn.XMATCH(B6&C6, 'User Input'!$B$7:$AAD$7&'User Input'!$B$8:$AAD$8)),"")} | J6: =IF(I6="","",I6*1000) | K6: ='[1]Inflation Factors'!$H4 -> 1.18745 | L6: =IF(AND(E6="",G6="",J6=""),"",(E6+G6+J6)*K6) | N6: =IF(L6="","",(C6*L6*(100%-'User Input'!$B$12))+(C6*J6*K6*'User Input'!$B$12)) | P6: =IF(AND(Ladder!A6>='User Input'!B$2, Ladder!A6<='User Input'!C$2),Ladder!A6,"") | Q6: =IF(P6="","", SUMIFS($L$4:$L$89, $B$4:$B$89, ">="&DATE(P6,1,1),$B$4:$B$89,"<"&DATE(P6+1,1,1))) | R6: {=IF(P6="","",IFERROR(INDEX('User Input'!$B$5:$DD$5,,_xlfn.XMATCH(P6,'User Input'!$B$4:$DD$4)),'User Input'!$B$3))} | S6: =IF(R6="","",(Q6+SUM(N6:N91)-R6))
A7: =IF(OR(TEXT(B6,"YYYY")<TEXT(B7,"YYYY"),ISBLANK(TEXT(B6,"YYYY"))),YEAR(B7),"") -> 2027 | B7: ='[1]Inflation Factors'!$C5 -> 46402 | C7: =('[1]Inflation Factors'!$B5)/100 -> 0.02375 | D7: {=IFERROR(INDEX('User Input'!$B$9:$AAD$9, ,_xlfn.XMATCH(B7&C7, 'User Input'!$B$7:$AAD$7&'User Input'!$B$8:$AAD$8)),"")} | E7: =IF(D7="","",D7*1000) | F7: {=IFERROR(INDEX('User Input'!$B$10:$AAD$10, ,_xlfn.XMATCH(B7&C7, 'User Input'!$B$7:$AAD$7&'User Input'!$B$8:$AAD$8)),"")} | G7: =IF(F7="","",F7*1000) | H7: =IF(F7="","",F7*1000*(100%-'User Input'!$B$12)) | I7: {=IFERROR(INDEX('User Input'!$B$11:$AAD$11, ,_xlfn.XMATCH(B7&C7, 'User Input'!$B$7:$AAD$7&'User Input'!$B$8:$AAD$8)),"")} | J7: =IF(I7="","",I7*1000) | K7: ='[1]Inflation Factors'!$H5 -> 1.609 | L7: =IF(AND(E7="",G7="",J7=""),"",(E7+G7+J7)*K7) | N7: =IF(L7="","",(C7*L7*(100%-'User Input'!$B$12))+(C7*J7*K7*'User Input'!$B$12)) | P7: =IF(AND(Ladder!A7>='User Input'!B$2, Ladder!A7<='User Input'!C$2),Ladder!A7,"") | Q7: =IF(P7="","", SUMIFS($L$4:$L$89, $B$4:$B$89, ">="&DATE(P7,1,1),$B$4:$B$89,"<"&DATE(P7+1,1,1))) | R7: {=IF(P7="","",IFERROR(INDEX('User Input'!$B$5:$DD$5,,_xlfn.XMATCH(P7,'User Input'!$B$4:$DD$4)),'User Input'!$B$3))} | S7: =IF(R7="","",(Q7+SUM(N7:N92)-R7))
A8: =IF(OR(TEXT(B7,"YYYY")<TEXT(B8,"YYYY"),ISBLANK(TEXT(B7,"YYYY"))),YEAR(B8),"") | B8: ='[1]Inflation Factors'!$C6 -> 46402 | C8: =('[1]Inflation Factors'!$B6)/100 -> 0.00375 | D8: {=IFERROR(INDEX('User Input'!$B$9:$AAD$9, ,_xlfn.XMATCH(B8&C8, 'User Input'!$B$7:$AAD$7&'User Input'!$B$8:$AAD$8)),"")} | E8: =IF(D8="","",D8*1000) | F8: {=IFERROR(INDEX('User Input'!$B$10:$AAD$10, ,_xlfn.XMATCH(B8&C8, 'User Input'!$B$7:$AAD$7&'User Input'!$B$8:$AAD$8)),"")} | G8: =IF(F8="","",F8*1000) | H8: =IF(F8="","",F8*1000*(100%-'User Input'!$B$12)) | I8: {=IFERROR(INDEX('User Input'!$B$11:$AAD$11, ,_xlfn.XMATCH(B8&C8, 'User Input'!$B$7:$AAD$7&'User Input'!$B$8:$AAD$8)),"")} | J8: =IF(I8="","",I8*1000) | K8: ='[1]Inflation Factors'!$H6 -> 1.34327 | L8: =IF(AND(E8="",G8="",J8=""),"",(E8+G8+J8)*K8) | N8: =IF(L8="","",(C8*L8*(100%-'User Input'!$B$12))+(C8*J8*K8*'User Input'!$B$12)) | P8: =IF(AND(Ladder!A8>='User Input'!B$2, Ladder!A8<='User Input'!C$2),Ladder!A8,"") | Q8: =IF(P8="","", SUMIFS($L$4:$L$89, $B$4:$B$89, ">="&DATE(P8,1,1),$B$4:$B$89,"<"&DATE(P8+1,1,1))) | R8: {=IF(P8="","",IFERROR(INDEX('User Input'!$B$5:$DD$5,,_xlfn.XMATCH(P8,'User Input'!$B$4:$DD$4)),'User Input'!$B$3))} | S8: =IF(R8="","",(Q8+SUM(N8:N93)-R8))
A9: =IF(OR(TEXT(B8,"YYYY")<TEXT(B9,"YYYY"),ISBLANK(TEXT(B8,"YYYY"))),YEAR(B9),"") | B9: ='[1]Inflation Factors'!$C7 -> 46492 | C9: =('[1]Inflation Factors'!$B7)/100 -> 0.00125 | D9: {=IFERROR(INDEX('User Input'!$B$9:$AAD$9, ,_xlfn.XMATCH(B9&C9, 'User Input'!$B$7:$AAD$7&'User Input'!$B$8:$AAD$8)),"")} | E9: =IF(D9="","",D9*1000) | F9: {=IFERROR(INDEX('User Input'!$B$10:$AAD$10, ,_xlfn.XMATCH(B9&C9, 'User Input'!$B$7:$AAD$7&'User Input'!$B$8:$AAD$8)),"")} | G9: =IF(F9="","",F9*1000) | H9: =IF(F9="","",F9*1000*(100%-'User Input'!$B$12)) | I9: {=IFERROR(INDEX('User Input'!$B$11:$AAD$11, ,_xlfn.XMATCH(B9&C9, 'User Input'!$B$7:$AAD$7&'User Input'!$B$8:$AAD$8)),"")} | J9: =IF(I9="","",I9*1000) | K9: ='[1]Inflation Factors'!$H7 -> 1.14922 | L9: =IF(AND(E9="",G9="",J9=""),"",(E9+G9+J9)*K9) | N9: =IF(L9="","",(C9*L9*(100%-'User Input'!$B$12))+(C9*J9*K9*'User Input'!$B$12)) | P9: =IF(AND(Ladder!A9>='User Input'!B$2, Ladder!A9<='User Input'!C$2),Ladder!A9,"") | Q9: =IF(P9="","", SUMIFS($L$4:$L$89, $B$4:$B$89, ">="&DATE(P9,1,1),$B$4:$B$89,"<"&DATE(P9+1,1,1))) | R9: {=IF(P9="","",IFERROR(INDEX('User Input'!$B$5:$DD$5,,_xlfn.XMATCH(P9,'User Input'!$B$4:$DD$4)),'User Input'!$B$3))} | S9: =IF(R9="","",(Q9+SUM(N9:N94)-R9))
A10: =IF(OR(TEXT(B9,"YYYY")<TEXT(B10,"YYYY"),ISBLANK(TEXT(B9,"YYYY"))),YEAR(B10),"") | B10: ='[1]Inflation Factors'!$C8 -> 46583 | C10: =('[1]Inflation Factors'!$B8)/100 -> 0.00375 | D10: {=IFERROR(INDEX('User Input'!$B$9:$AAD$9, ,_xlfn.XMATCH(B10&C10, 'User Input'!$B$7:$AAD$7&'User Input'!$B$8:$AAD$8)),"")} | E10: =IF(D10="","",D10*1000) | F10: {=IFERROR(INDEX('User Input'!$B$10:$AAD$10, ,_xlfn.XMATCH(B10&C10, 'User Input'!$B$7:$AAD$7&'User Input'!$B$8:$AAD$8)),"")} | G10: =IF(F10="","",F10*1000) | H10: =IF(F10="","",F10*1000*(100%-'User Input'!$B$12)) | I10: {=IFERROR(INDEX('User Input'!$B$11:$AAD$11, ,_xlfn.XMATCH(B10&C10, 'User Input'!$B$7:$AAD$7&'User Input'!$B$8:$AAD$8)),"")} | J10: =IF(I10="","",I10*1000) | K10: ='[1]Inflation Factors'!$H8 -> 1.32647 | L10: =IF(AND(E10="",G10="",J10=""),"",(E10+G10+J10)*K10) | N10: =IF(L10="","",(C10*L10*(100%-'User Input'!$B$12))+(C10*J10*K10*'User Input'!$B$12)) | P10: =IF(AND(Ladder!A10>='User Input'!B$2, Ladder!A10<='User Input'!C$2),Ladder!A10,"") | Q10: =IF(P10="","", SUMIFS($L$4:$L$89, $B$4:$B$89, ">="&DATE(P10,1,1),$B$4:$B$89,"<"&DATE(P10+1,1,1))) | R10: {=IF(P10="","",IFERROR(INDEX('User Input'!$B$5:$DD$5,,_xlfn.XMATCH(P10,'User Input'!$B$4:$DD$4)),'User Input'!$B$3))} | S10: =IF(R10="","",(Q10+SUM(N10:N95)-R10))
A11: =IF(OR(TEXT(B10,"YYYY")<TEXT(B11,"YYYY"),ISBLANK(TEXT(B10,"YYYY"))),YEAR(B11),"") | B11: ='[1]Inflation Factors'!$C9 -> 46675 | C11: =('[1]Inflation Factors'!$B9)/100 -> 0.01625 | D11: {=IFERROR(INDEX('User Input'!$B$9:$AAD$9, ,_xlfn.XMATCH(B11&C11, 'User Input'!$B$7:$AAD$7&'User Input'!$B$8:$AAD$8)),"")} | E11: =IF(D11="","",D11*1000) | F11: {=IFERROR(INDEX('User Input'!$B$10:$AAD$10, ,_xlfn.XMATCH(B11&C11, 'User Input'!$B$7:$AAD$7&'User Input'!$B$8:$AAD$8)),"")} | G11: =IF(F11="","",F11*1000) | H11: =IF(F11="","",F11*1000*(100%-'User Input'!$B$12)) | I11: {=IFERROR(INDEX('User Input'!$B$11:$AAD$11, ,_xlfn.XMATCH(B11&C11, 'User Input'!$B$7:$AAD$7&'User Input'!$B$8:$AAD$8)),"")} | J11: =IF(I11="","",I11*1000) | K11: ='[1]Inflation Factors'!$H9 -> 1.09537 | L11: =IF(AND(E11="",G11="",J11=""),"",(E11+G11+J11)*K11) | N11: =IF(L11="","",(C11*L11*(100%-'User Input'!$B$12))+(C11*J11*K11*'User Input'!$B$12)) | P11: =IF(AND(Ladder!A11>='User Input'!B$2, Ladder!A11<='User Input'!C$2),Ladder!A11,"") | Q11: =IF(P11="","", SUMIFS($L$4:$L$89, $B$4:$B$89, ">="&DATE(P11,1,1),$B$4:$B$89,"<"&DATE(P11+1,1,1))) | R11: {=IF(P11="","",IFERROR(INDEX('User Input'!$B$5:$DD$5,,_xlfn.XMATCH(P11,'User Input'!$B$4:$DD$4)),'User Input'!$B$3))} | S11: =IF(R11="","",(Q11+SUM(N11:N96)-R11))
A12: =IF(OR(TEXT(B11,"YYYY")<TEXT(B12,"YYYY"),ISBLANK(TEXT(B11,"YYYY"))),YEAR(B12),"") -> 2028 | B12: ='[1]Inflation Factors'!$C10 -> 46767 | C12: =('[1]Inflation Factors'!$B10)/100 -> 0.0175 | D12: {=IFERROR(INDEX('User Input'!$B$9:$AAD$9, ,_xlfn.XMATCH(B12&C12, 'User Input'!$B$7:$AAD$7&'User Input'!$B$8:$AAD$8)),"")} | E12: =IF(D12="","",D12*1000) | F12: {=IFERROR(INDEX('User Input'!$B$10:$AAD$10, ,_xlfn.XMATCH(B12&C12, 'User Input'!$B$7:$AAD$7&'User Input'!$B$8:$AAD$8)),"")} | G12: =IF(F12="","",F12*1000) | H12: =IF(F12="","",F12*1000*(100%-'User Input'!$B$12)) | I12: {=IFERROR(INDEX('User Input'!$B$11:$AAD$11, ,_xlfn.XMATCH(B12&C12, 'User Input'!$B$7:$AAD$7&'User Input'!$B$8:$AAD$8)),"")} | J12: =IF(I12="","",I12*1000) | K12: ='[1]Inflation Factors'!$H10 -> 1.54885 | L12: =IF(AND(E12="",G12="",J12=""),"",(E12+G12+J12)*K12) | N12: =IF(L12="","",(C12*L12*(100%-'User Input'!$B$12))+(C12*J12*K12*'User Input'!$B$12)) | P12: =IF(AND(Ladder!A12>='User Input'!B$2, Ladder!A12<='User Input'!C$2),Ladder!A12,"") -> 2028 | Q12: =IF(P12="","", SUMIFS($L$4:$L$89, $B$4:$B$89, ">="&DATE(P12,1,1),$B$4:$B$89,"<"&DATE(P12+1,1,1))) -> 32886.5 | R12: {=IF(P12="","",IFERROR(INDEX('User Input'!$B$5:$DD$5,,_xlfn.XMATCH(P12,'User Input'!$B$4:$DD$4)),'User Input'!$B$3))} -> 37000 | S12: =IF(R12="","",(Q12+SUM(N12:N97)-R12)) -> 7860.0226
A13: =IF(OR(TEXT(B12,"YYYY")<TEXT(B13,"YYYY"),ISBLANK(TEXT(B12,"YYYY"))),YEAR(B13),"") | B13: ='[1]Inflation Factors'!$C11 -> 46767 | C13: =('[1]Inflation Factors'!$B11)/100 -> 0.005 | D13: {=IFERROR(INDEX('User Input'!$B$9:$AAD$9, ,_xlfn.XMATCH(B13&C13, 'User Input'!$B$7:$AAD$7&'User Input'!$B$8:$AAD$8)),"")} -> 25 | E13: =IF(D13="","",D13*1000) -> 25000 | F13: {=IFERROR(INDEX('User Input'!$B$10:$AAD$10, ,_xlfn.XMATCH(B13&C13, 'User Input'!$B$7:$AAD$7&'User Input'!$B$8:$AAD$8)),"")} -> 0 | G13: =IF(F13="","",F13*1000) -> 0 | H13: =IF(F13="","",F13*1000*(100%-'User Input'!$B$12)) -> 0 | I13: {=IFERROR(INDEX('User Input'!$B$11:$AAD$11, ,_xlfn.XMATCH(B13&C13, 'User Input'!$B$7:$AAD$7&'User Input'!$B$8:$AAD$8)),"")} -> 0 | J13: =IF(I13="","",I13*1000) -> 0 | K13: ='[1]Inflation Factors'!$H11 -> 1.31546 | L13: =IF(AND(E13="",G13="",J13=""),"",(E13+G13+J13)*K13) -> 32886.5 | N13: =IF(L13="","",(C13*L13*(100%-'User Input'!$B$12))+(C13*J13*K13*'User Input'!$B$12)) -> 124.9687 | P13: =IF(AND(Ladder!A13>='User Input'!B$2, Ladder!A13<='User Input'!C$2),Ladder!A13,"") | Q13: =IF(P13="","", SUMIFS($L$4:$L$89, $B$4:$B$89, ">="&DATE(P13,1,1),$B$4:$B$89,"<"&DATE(P13+1,1,1))) | R13: {=IF(P13="","",IFERROR(INDEX('User Input'!$B$5:$DD$5,,_xlfn.XMATCH(P13,'User Input'!$B$4:$DD$4)),'User Input'!$B$3))} | S13: =IF(R13="","",(Q13+SUM(N13:N98)-R13))
A14: =IF(OR(TEXT(B13,"YYYY")<TEXT(B14,"YYYY"),ISBLANK(TEXT(B13,"YYYY"))),YEAR(B14),"") | B14: ='[1]Inflation Factors'!$C12 -> 46858 | C14: =('[1]Inflation Factors'!$B12)/100 -> 0.03625 | D14: {=IFERROR(INDEX('User Input'!$B$9:$AAD$9, ,_xlfn.XMATCH(B14&C14, 'User Input'!$B$7:$AAD$7&'User Input'!$B$8:$AAD$8)),"")} | E14: =IF(D14="","",D14*1000) | F14: {=IFERROR(INDEX('User Input'!$B$10:$AAD$10, ,_xlfn.XMATCH(B14&C14, 'User Input'!$B$7:$AAD$7&'User Input'!$B$8:$AAD$8)),"")} | G14: =IF(F14="","",F14*1000) | H14: =IF(F14="","",F14*1000*(100%-'User Input'!$B$12)) | I14: {=IFERROR(INDEX('User Input'!$B$11:$AAD$11, ,_xlfn.XMATCH(B14&C14, 'User Input'!$B$7:$AAD$7&'User Input'!$B$8:$AAD$8)),"")} | J14: =IF(I14="","",I14*1000) | K14: ='[1]Inflation Factors'!$H12 -> 2.00618 | L14: =IF(AND(E14="",G14="",J14=""),"",(E14+G14+J14)*K14) | N14: =IF(L14="","",(C14*L14*(100%-'User Input'!$B$12))+(C14*J14*K14*'User Input'!$B$12)) | P14: =IF(AND(Ladder!A14>='User Input'!B$2, Ladder!A14<='User Input'!C$2),Ladder!A14,"") | Q14: =IF(P14="","", SUMIFS($L$4:$L$89, $B$4:$B$89, ">="&DATE(P14,1,1),$B$4:$B$89,"<"&DATE(P14+1,1,1))) | R14: {=IF(P14="","",IFERROR(INDEX('User Input'!$B$5:$DD$5,,_xlfn.XMATCH(P14,'User Input'!$B$4:$DD$4)),'User Input'!$B$3))} | S14: =IF(R14="","",(Q14+SUM(N14:N99)-R14))
A15: =IF(OR(TEXT(B14,"YYYY")<TEXT(B15,"YYYY"),ISBLANK(TEXT(B14,"YYYY"))),YEAR(B15),"") | B15: ='[1]Inflation Factors'!$C13 -> 46858 | C15: =('[1]Inflation Factors'!$B13)/100 -> 0.0125 | D15: {=IFERROR(INDEX('User Input'!$B$9:$AAD$9, ,_xlfn.XMATCH(B15&C15, 'User Input'!$B$7:$AAD$7&'User Input'!$B$8:$AAD$8)),"")} | E15: =IF(D15="","",D15*1000) | F15: {=IFERROR(INDEX('User Input'!$B$10:$AAD$10, ,_xlfn.XMATCH(B15&C15, 'User Input'!$B$7:$AAD$7&'User Input'!$B$8:$AAD$8)),"")} | G15: =IF(F15="","",F15*1000) | H15: =IF(F15="","",F15*1000*(100%-'User Input'!$B$12)) | I15: {=IFERROR(INDEX('User Input'!$B$11:$AAD$11, ,_xlfn.XMATCH(B15&C15, 'User Input'!$B$7:$AAD$7&'User Input'!$B$8:$AAD$8)),"")} | J15: =IF(I15="","",I15*1000) | K15: ='[1]Inflation Factors'!$H13 -> 1.08178 | L15: =IF(AND(E15="",G15="",J15=""),"",(E15+G15+J15)*K15) | N15: =IF(L15="","",(C15*L15*(100%-'User Input'!$B$12))+(C15*J15*K15*'User Input'!$B$12)) | P15: =IF(AND(Ladder!A15>='User Input'!B$2, Ladder!A15<='User Input'!C$2),Ladder!A15,"") | Q15: =IF(P15="","", SUMIFS($L$4:$L$89, $B$4:$B$89, ">="&DATE(P15,1,1),$B$4:$B$89,"<"&DATE(P15+1,1,1))) | R15: {=IF(P15="","",IFERROR(INDEX('User Input'!$B$5:$DD$5,,_xlfn.XMATCH(P15,'User Input'!$B$4:$DD$4)),'User Input'!$B$3))} | S15: =IF(R15="","",(Q15+SUM(N15:N100)-R15))
... A66: =IF(OR(TEXT(B65,"YYYY")<TEXT(B66,"YYYY"),ISBLANK(TEXT(B65,"YYYY"))),YEAR(B66),"") | B66: ='[1]Inflation Factors'!$C64 -> 0 | C66: =('[1]Inflation Factors'!$B64)/100 -> 0 | D66: {=IFERROR(INDEX('User Input'!$B$9:$AAD$9, ,_xlfn.XMATCH(B66&C66, 'User Input'!$B$7:$AAD$7&'User Input'!$B$8:$AAD$8)),"")} | E66: =IF(D66="","",D66*1000) | F66: {=IFERROR(INDEX('User Input'!$B$10:$AAD$10, ,_xlfn.XMATCH(B66&C66, 'User Input'!$B$7:$AAD$7&'User Input'!$B$8:$AAD$8)),"")} | G66: =IF(F66="","",F66*1000) | H66: =IF(F66="","",F66*1000*(100%-'User Input'!$B$12)) | I66: {=IFERROR(INDEX('User Input'!$B$11:$AAD$11, ,_xlfn.XMATCH(B66&C66, 'User Input'!$B$7:$AAD$7&'User Input'!$B$8:$AAD$8)),"")} | J66: =IF(I66="","",I66*1000) | K66: ='[1]Inflation Factors'!$H64 -> 0 | L66: =IF(AND(E66="",G66="",J66=""),"",(E66+G66+J66)*K66) | N66: =IF(L66="","",(C66*L66*(100%-'User Input'!$B$12))+(C66*J66*K66*'User Input'!$B$12)) | P66: =IF(AND(Ladder!A66>='User Input'!B$2, Ladder!A66<='User Input'!C$2),Ladder!A66,"") | Q66: =IF(P66="","", SUMIFS($L$4:$L$89, $B$4:$B$89, ">="&DATE(P66,1,1),$B$4:$B$89,"<"&DATE(P66+1,1,1))) | R66: {=IF(P66="","",IFERROR(INDEX('User Input'!$B$5:$DD$5,,_xlfn.XMATCH(P66,'User Input'!$B$4:$DD$4)),'User Input'!$B$3))} | S66: =IF(R66="","",(Q66+SUM(N66:N151)-R66))
J67: =IF(I67="","",I67*1000) | L67: =IF(AND(E67="",H67="",J67=""),"",(E67+H67+J67)*K67) | N67: =IF(L67="","",(C67*L67*(100%-'User Input'!$B$12))+(C67*J67*K67*'User Input'!$B$12))
J68: =IF(I68="","",I68*1000) | L68: =IF(AND(E68="",H68="",J68=""),"",(E68+H68+J68)*K68) | N68: =IF(L68="","",(C68*L68*(100%-'User Input'!$B$12))+(C68*J68*K68*'User Input'!$B$12))
J69: =IF(I69="","",I69*1000)
J70: =IF(I70="","",I70*1000)
J71: =IF(I71="","",I71*1000)
J72: =IF(I72="","",I72*1000)
J73: =IF(I73="","",I73*1000)
J74: =IF(I74="","",I74*1000)
J75: =IF(I75="","",I75*1000)
J76: =IF(I76="","",I76*1000)
J77: =IF(I77="","",I77*1000)
J78: =IF(I78="","",I78*1000)
J79: =IF(I79="","",I79*1000)
J80: =IF(I80="","",I80*1000)
... J88: =IF(I88="","",I88*1000)

Sheet Fidelity_FixedIncome_SearchResu
A1: Cusip | B1: State | C1: Description | D1: Coupon | E1: Maturity Date | F1: Moody's Rating | G1: S&P Rating | H1: Price Bid | I1: Price Ask | J1: Yield Bid | K1: Ask Yield to Worst | L1: Ask Yield to Maturity | M1: Inflation Factor | N1: Adjusted Price Bid | O1: Adjusted Price Ask | P1: Attributes
A2: ="91282CCA7" -> 91282CCA7 | B2: N/A | C2: UNITED STATES TREAS NTS SER X-2026 0.12500% 04/15/2026 | D2: 0.125 | E2: 46127 | F2: AA1 | G2: -- | H2: 99.842 | I2: 99.876 | J2: 0.892 | K2: 0.727 | L2: 0.727 | M2: 1.23629 | N2: 123.43367 | O2: 123.4757 | P2: CP D
A3: ="912828S50" -> 912828S50 | B3: N/A | C3: UNITED STATES TREAS NTS 0.12500% 07/15/2026 TIPS | D3: 0.125 | E3: 46218 | F3: AA1 | G3: -- | H3: 100.186 | I3: 100.211 | J3: -0.281 | K3: -0.335 | L3: -0.335 | M3: 1.35259 | N3: 135.51058 | O3: 135.5444 | P3: CP D
A4: ="91282CDC2" -> 91282CDC2 | B4: N/A | C4: UNITED STATES TREAS NTS SER AE-2026 0.12500% 10/15/2026 | D4: 0.125 | E4: 46310 | F4: AA1 | G4: -- | H4: 99.868 | I4: 99.891 | J4: 0.312 | K4: 0.279 | L4: 0.279 | M4: 1.18649 | N4: 118.49238 | O4: 118.51967 | P4: CP D
A5: ="912810PS1" -> 912810PS1 | B5: N/A | C5: UNITED STATES TREAS BDS TIPS 2.37500% 01/15/2027 | D5: 2.375 | E5: 46402 | F5: AA1 | G5: -- | H5: 101.405 | I5: 101.462 | J5: 0.899 | K5: 0.84 | L5: 0.84 | M5: 1.60771 | N5: 163.02983 | O5: 163.12147 | P5: CP D
A6: ="912828V49" -> 912828V49 | B6: N/A | C6: UNITED STATES TREAS NTS TIPS 0.37500% 01/15/2027 | D6: 0.375 | E6: 46402 | F6: AA1 | G6: -- | H6: 99.497 | I6: 99.533 | J6: 0.902 | K6: 0.865 | L6: 0.865 | M6: 1.34219 | N6: 133.54388 | O6: 133.5922 | P6: CP D
A7: ="91282CEJ6" -> 91282CEJ6 | B7: N/A | C7: UNITED STATES TREAS NTS SER X-2027 0.12500% 04/15/2027 | D7: 0.125 | E7: 46492 | F7: AA1 | G7: -- | H7: 98.908 | I7: 98.944 | J7: 1.038 | K7: 1.008 | L7: 1.008 | M7: 1.1483 | N7: 113.57606 | O7: 113.6174 | P7: CP D
A8: ="9128282L3" -> 9128282L3 | B8: N/A | C8: UNITED STATES TREAS NTS SER D-2027 0.37500% 07/15/2027 | D8: 0.375 | E8: 46583 | F8: AA1 | G8: -- | H8: 99.604 | I8: 99.645 | J8: 0.648 | K8: 0.619 | L8: 0.619 | M8: 1.3254 | N8: 132.01514 | O8: 132.06948 | P8: CP D
A9: ="91282CFR7" -> 91282CFR7 | B9: N/A | C9: UNITED STATES TREAS NTS SER AE-2027 1.62500% 10/15/2027 | D9: 1.625 | E9: 46675 | F9: AA1 | G9: -- | H9: 101.489 | I9: 101.521 | J9: 0.745 | K9: 0.726 | L9: 0.726 | M9: 1.09448 | N9: 111.07768 | O9: 111.1127 | P9: CP D
A10: ="912810PV4" -> 912810PV4 | B10: N/A | C10: UNITED STATES TREASURY 1.75000% 01/15/2028 | D10: 1.75 | E10: 46767 | F10: AA1 | G10: -- | H10: 101.512 | I10: 101.565 | J10: 0.968 | K10: 0.941 | L10: 0.941 | M10: 1.5476 | N10: 157.09997 | O10: 157.18199 | P10: CP D
A11: ="9128283R9" -> 9128283R9 | B11: N/A | C11: UNITED STATES TREAS NTS SER A-2028 0.50000% 01/15/2028 | D11: 0.5 | E11: 46767 | F11: AA1 | G11: -- | H11: 99.097 | I11: 99.128 | J11: 0.966 | K11: 0.95 | L11: 0.95 | M11: 1.3144 | N11: 130.2531 | O11: 130.29384 | P11: CP D
A12: ="912810FD5" -> 912810FD5 | B12: N/A | C12: UNITED STATES TREAS BDS 3.62500% 04/15/2028 | D12: 3.625 | E12: 46858 | F12: AA1 | G12: -- | H12: 105.607 | I12: 105.668 | J12: 1.047 | K12: 1.018 | L12: 1.018 | M12: 2.00456 | N12: 211.69557 | O12: 211.81785 | P12: CP D
A13: ="91282CGW5" -> 91282CGW5 | B13: N/A | C13: UNITED STATES TREAS NTS SER X-2028 1.25000% 04/15/2028 | D13: 1.25 | E13: 46858 | F13: AA1 | G13: -- | H13: 100.419 | I13: 100.447 | J13: 1.057 | K13: 1.044 | L13: 1.044 | M13: 1.08091 | N13: 108.5439 | O13: 108.57417 | P13: CP D
A14: ="912828Y38" -> 912828Y38 | B14: N/A | C14: UNITED STATES TREAS NTS SER D-2028 0.75000% 07/15/2028 | D14: 0.75 | E14: 46949 | F14: AA1 | G14: -- | H14: 99.747 | I14: 99.784 | J14: 0.854 | K14: 0.838 | L14: 0.838 | M14: 1.29162 | N14: 128.83522 | O14: 128.88301 | P14: CP D
A15: ="91282CJH5" -> 91282CJH5 | B15: N/A | C15: UNITED STATES TREAS NTS SER AE-2028 2.37500% 10/15/2028 | D15: 2.375 | E15: 47041 | F15: AA1 | G15: -- | H15: 103.841 | I15: 103.877 | J15: 0.934 | K15: 0.92 | L15: 0.92 | M15: 1.05852 | N15: 109.91778 | O15: 109.95588 | P15: CP D
A16: ="912810PZ5" -> 912810PZ5 | B16: N/A | C16: UNITED STATES TREAS BDS 2.50000% 01/15/2029 TIPS | D16: 2.5 | E16: 47133 | F16: AA1 | G16: -- | H16: 104.087 | I16: 104.148 | J16: 1.092 | K16: 1.071 | L16: 1.071 | M16: 1.5101 | N16: 157.18178 | O16: 157.27389 | P16: CP D
A17: ="9128285W6" -> 9128285W6 | B17: N/A | C17: UNITED STATES TREAS NTS SER A-2029 0.87500% 01/15/2029 | D17: 0.875 | E17: 47133 | F17: AA1 | G17: -- | H17: 99.417 | I17: 99.447 | J17: 1.075 | K17: 1.065 | L17: 1.065 | M17: 1.28402 | N17: 127.65342 | O17: 127.69194 | P17: CP D
A18: ="912810FH6" -> 912810FH6 | B18: N/A | C18: UNITED STATES TREAS BDS 3.87500% 04/15/2029 | D18: 3.875 | E18: 47223 | F18: AA1 | G18: -- | H18: 108.553 | I18: 108.61 | J18: 1.15 | K18: 1.132 | L18: 1.132 | M18: 1.97221 | N18: 214.08931 | O18: 214.20173 | P18: CP D
A19: ="91282CKL4" -> 91282CKL4 | B19: N/A | C19: UNITED STATES TREAS NTS SER X-2029 2.12500% 04/15/2029 | D19: 2.125 | E19: 47223 | F19: AA1 | G19: -- | H19: 103.053 | I19: 103.087 | J19: 1.152 | K19: 1.141 | L19: 1.141 | M19: 1.0482 | N19: 108.02015 | O19: 108.05579 | P19: CP D
A20: ="9128287D6" -> 9128287D6 | B20: N/A | C20: UNITED STATES TREAS NTS SER D-2029 0.25000% 07/15/2029 | D20: 0.25 | E20: 47314 | F20: AA1 | G20: -- | H20: 97.426 | I20: 97.463 | J20: 1.009 | K20: 0.998 | L20: 0.998 | M20: 1.2675 | N20: 123.48745 | O20: 123.53435 | P20: CP D
A21: ="91282CLV1" -> 91282CLV1 | B21: N/A | C21: UNITED STATES TREAS NTS SER AE-2029 1.62500% 10/15/2029 | D21: 1.625 | E21: 47406 | F21: AA1 | G21: -- | H21: 101.974 | I21: 102.01 | J21: 1.08 | K21: 1.07 | L21: 1.07 | M21: 1.03039 | N21: 105.07299 | O21: 105.11008 | P21: CP D
A22: ="912828Z37" -> 912828Z37 | B22: N/A | C22: UNITED STATES TREAS NTS SER A-2030 0.12500% 01/15/2030 | D22: 0.125 | E22: 47498 | F22: AA1 | G22: -- | H22: 95.919 | I22: 95.955 | J22: 1.183 | K22: 1.173 | L22: 1.173 | M22: 1.26016 | N22: 120.87329 | O22: 120.91865 | P22: CP D
A23: ="91282CNB3" -> 91282CNB3 | B23: N/A | C23: UNITED STATES TREAS NTS SER X-2030 1.62500% 04/15/2030 | D23: 1.625 | E23: 47588 | F23: AA1 | G23: -- | H23: 101.513 | I23: 101.548 | J23: 1.254 | K23: 1.245 | L23: 1.245 | M23: 1.0185 | N23: 103.39099 | O23: 103.42664 | P23: CP D
A24: ="912828ZZ6" -> 912828ZZ6 | B24: N/A | C24: UNITED STATES TREAS NTS SER D-2030 0.12500% 07/15/2030 | D24: 0.125 | E24: 47679 | F24: AA1 | G24: -- | H24: 95.514 | I24: 95.54 | J24: 1.16 | K24: 1.154 | L24: 1.154 | M24: 1.26454 | N24: 120.78127 | O24: 120.81415 | P24: CP D
A25: ="91282CPH8" -> 91282CPH8 | B25: N/A | C25: UNITED STATES TREAS NTS SER AE-2030 1.12500% 10/15/2030 | D25: 1.125 | E25: 47771 | F25: AA1 | G25: -- | H25: 99.552 | I25: 99.58 | J25: 1.223 | K25: 1.217 | L25: 1.217 | M25: 1.00232 | N25: 99.78296 | O25: 99.811025 | P25: CP D
A26: ="91282CBF7" -> 91282CBF7 | B26: N/A | C26: UNITED STATES TREAS NTS SER A-2031 0.12500% 01/15/2031 | D26: 0.125 | E26: 47863 | F26: AA1 | G26: -- | H26: 94.341 | I26: 94.374 | J26: 1.307 | K26: 1.3 | L26: 1.3 | M26: 1.24548 | N26: 117.49983 | O26: 117.54093 | P26: CP D
A27: ="91282CCM1" -> 91282CCM1 | B27: N/A | C27: UNITED STATES TREAS NTS SER D-2031 0.12500% 07/15/2031 | D27: 0.125 | E27: 48044 | F27: AA1 | G27: -- | H27: 93.82 | I27: 93.859 | J27: 1.302 | K27: 1.293 | L27: 1.293 | M27: 1.20967 | N27: 113.49124 | O27: 113.53842 | P27: CP D
A28: ="91282CDX6" -> 91282CDX6 | B28: N/A | C28: UNITED STATES TREAS NTS SER A-2032 0.12500% 01/15/2032 | D28: 0.125 | E28: 48228 | F28: AA1 | G28: -- | H28: 92.508 | I28: 92.538 | J28: 1.442 | K28: 1.436 | L28: 1.436 | M28: 1.1696 | N28: 108.19736 | O28: 108.23244 | P28: CP D
A29: ="912810FQ6" -> 912810FQ6 | B29: N/A | C29: UNITED STATES TREASURY 3.37500% 04/15/2032 | D29: 3.375 | E29: 48319 | F29: AA1 | G29: -- | H29: 111.395 | I29: 111.479 | J29: 1.448 | K29: 1.434 | L29: 1.434 | M29: 1.82658 | N29: 203.47188 | O29: 203.62531 | P29: CP D
A30: ="91282CEZ0" -> 91282CEZ0 | B30: N/A | C30: UNITED STATES TREAS NTS SER D-2032 0.62500% 07/15/2032 | D30: 0.625 | E30: 48410 | F30: AA1 | G30: -- | H30: 94.905 | I30: 94.951 | J30: 1.454 | K30: 1.446 | L30: 1.446 | M30: 1.11588 | N30: 105.90259 | O30: 105.95392 | P30: CP D
A31: ="91282CGK1" -> 91282CGK1 | B31: N/A | C31: UNITED STATES TREAS NTS SER A-2033 1.12500% 01/15/2033 | D31: 1.125 | E31: 48594 | F31: AA1 | G31: -- | H31: 97.029 | I31: 97.063 | J31: 1.577 | K31: 1.572 | L31: 1.572 | M31: 1.08843 | N31: 105.60927 | O31: 105.64628 | P31: CP D
A32: ="91282CHP9" -> 91282CHP9 | B32: N/A | C32: UNITED STATES TREAS NTS SER D-2033 1.37500% 07/15/2033 | D32: 1.375 | E32: 48775 | F32: AA1 | G32: -- | H32: 98.557 | I32: 98.583 | J32: 1.581 | K32: 1.577 | L32: 1.577 | M32: 1.06753 | N32: 105.21255 | O32: 105.24031 | P32: CP D
A33: ="91282CJY8" -> 91282CJY8 | B33: N/A | C33: UNITED STATES TREAS NTS SER A-2034 1.75000% 01/15/2034 | D33: 1.75 | E33: 48959 | F33: AA1 | G33: -- | H33: 100.433 | I33: 100.469 | J33: 1.692 | K33: 1.686 | L33: 1.686 | M33: 1.05474 | N33: 105.9307 | O33: 105.96867 | P33: CP D
A34: ="91282CLE9" -> 91282CLE9 | B34: N/A | C34: UNITED STATES TREAS NTS SER D-2034 1.87500% 07/15/2034 | D34: 1.875 | E34: 49140 | F34: AA1 | G34: -- | H34: 101.382 | I34: 101.398 | J34: 1.699 | K34: 1.696 | L34: 1.696 | M34: 1.03325 | N34: 104.75295 | O34: 104.76948 | P34: CP D
A35: ="91282CML2" -> 91282CML2 | B35: N/A | C35: UNITED STATES TREAS NTS SER A-2035 2.12500% 01/15/2035 | D35: 2.125 | E35: 49324 | F35: AA1 | G35: -- | H35: 102.681 | I35: 102.712 | J35: 1.799 | K35: 1.795 | L35: 1.795 | M35: 1.02735 | N35: 105.48932 | O35: 105.52117 | P35: CP D
A36: ="91282CNS6" -> 91282CNS6 | B36: N/A | C36: UNITED STATES TREAS NTS SER D-2035 1.87500% 07/15/2035 | D36: 1.875 | E36: 49505 | F36: AA1 | G36: -- | H36: 100.596 | I36: 100.616 | J36: 1.806 | K36: 1.803 | L36: 1.803 | M36: 1.00972 | N36: 101.57379 | O36: 101.59399 | P36: CP D
A37: ="91282CPU9" -> 91282CPU9 | B37: N/A | C37: UNITED STATES TREAS NTS SER A-2036 1.87500% 01/15/2036 | D37: 1.875 | E37: 49689 | F37: AA1 | G37: -- | H37: 99.926 | I37: 99.956 | J37: 1.883 | K37: 1.879 | L37: 1.879 | M37: 0.99779 | N37: 99.705163 | O37: 99.735097 | P37: CP D
A38: ="912810QF8" -> 912810QF8 | B38: N/A | C38: UNITED STATES TREAS BDS 2.12500% 02/15/2040 | D38: 2.125 | E38: 51181 | F38: AA1 | G38: -- | H38: 99.61 | I38: 99.689 | J38: 2.157 | K38: 2.15 | L38: 2.15 | M38: 1.50004 | N38: 149.41898 | O38: 149.53749 | P38: CP D
A39: ="912810QP6" -> 912810QP6 | B39: N/A | C39: UNITED STATES TREAS BDS 2.12500% 02/15/2041 | D39: 2.125 | E39: 51547 | F39: AA1 | G39: -- | H39: 98.618 | I39: 98.698 | J39: 2.234 | K39: 2.227 | L39: 2.227 | M39: 1.48051 | N39: 146.00493 | O39: 146.12338 | P39: CP D
A40: ="912810QV3" -> 912810QV3 | B40: N/A | C40: UNITED STATES TREAS BDS 0.75000% 02/15/2042 TIPS | D40: 0.75 | E40: 51912 | F40: AA1 | G40: -- | H40: 78.507 | I40: 78.598 | J40: 2.368 | K40: 2.36 | L40: 2.36 | M40: 1.43484 | N40: 112.64498 | O40: 112.77555 | P40: CP D
...
